Workbook

Sheet PRECIOS TODOS
A1: 45944
A2: *Rollo x 10mts. Tejido romb. x 2,00 mt*
A3: *CALIDAD ECONOMICA*
A4: -Cal 14 c/rombos de 3 ½'' | B4: 65445.028
A5: -Cal 14 c/rombos de 3'' | B5: 80651.34
A6: *CALIDAD STANDARD*
A7: -Cal 14 c/rombos de 2 ½" | B7: 99041.404
A8: -Cal 14 c/rombos de 2'' | B8: 115550.16
A9: -Cal 12 c/rombos de 3 ½'' | B9: 100199.13
A10: -Cal 12 c/rombos de 3'' | B10: 110796.8
A11: *CALIDAD REFORZADA*
A12: -Cal 12 c/rombos de 2 ½" | B12: 152463.87
A13: -Cal 12 c/rombos de 2'' | B13: 169451.3
A15: La resistencia del rollo está sujeta al calibre del alambre y el tamaño del rombo
A18: *Rollo x 10mts. Tejido romb. x 1,80 mt*
A19: *CALIDAD ECONOMICA*
A20: -Cal 14 c/rombos de 3 ½'' | B20: 60190.724
A21: -Cal 14 c/rombos de 3'' | B21: 75252.32
A22: *CALIDAD STANDARD*
A23: -Cal 14 c/rombos de 2 ½" | B23: 87798.084
A24: -Cal 14 c/rombos de 2'' | B24: 103583.26
A25: -Cal 12 c/rombos de 3 ½'' | B25: 90325.048
A26: -Cal 12 c/rombos de 3'' | B26: 99475.552
A27: *CALIDAD REFORZADA*
A28: -Cal 12 c/rombos de 2 ½" | B28: 135487.57
A29: -Cal 12 c/rombos de 2'' | B29: 163662.66
A31: La resistencia del rollo está sujeta al calibre del alambre y el tamaño del rombo
A34: *Rollo x 10mts. Tejido romb. x 1,50 mt*
A35: *CALIDAD ECONOMICA*
A36: -Cal 14 c/rombos de 3 ½'' | B36: 50672.864
A37: -Cal 14 c/rombos de 3'' | B37: 62272.408
A38: *CALIDAD STANDARD*
A39: -Cal 14 c/rombos de 2 ½" | B39: 72012.908
A40: -Cal 14 c/rombos de 2'' | B40: 87798.084
A41: -Cal 12 c/rombos de 3 ½'' | B41: 76231.936
A42: -Cal 12 c/rombos de 3'' | B42: 85382.44
A43: *CALIDAD REFORZADA*
A44: -Cal 12 c/rombos de 2 ½" | B44: 115004.69
A45: -Cal 12 c/rombos de 2'' | B45: 121394.46
A47: La resistencia del rollo está sujeta al calibre del alambre y el tamaño del rombo
...

Sheet Cerco con rollo de 2mt
B1: DIMENSION | C1: 60x30
B2: MTL | C2: 180 | I2: Presupuesto | L2: Calculos Auxiliares
A3: Grupo | B3: Accesorios | C3: Un. Medida | D3: Cantidad | E3: Precio x Unidad | F3: Sub Total | G3: TOTAL | I3: Tipo Tejido | J3: Rollo C14x 2mt x 3 1/2" | L3: =SUMIFS(G4:G11,B4:B11,J3) -> 1178010.5 | M3: Instalacion
A4: TEJIDO | B4: Rollo C14x 2mt x 3 1/2" | C4: un | D4: =$C$2/10 -> 18 | E4: ='PRECIOS TODOS'!B4 -> 65445.028 | F4: =D4*E4 -> 1178010.5 | G4: =F4 -> 1178010.5 | I4: Tipo Poste | J4: POSTE EUCALIPTO | L4: =SUMIFS(F22:F33,A22:A33,J4) -> 1110000 | M4: =G12+G43 -> 5688371.6
A5: TEJIDO | B5: Rollo C14x 2mt x 3" | C5: un | D5: =$C$2/10 -> 18 | E5: ='PRECIOS TODOS'!B5 -> 80651.34 | F5: =D5*E5 -> 1451724.1 | G5: =F5 -> 1451724.1 | I5: Tipo Cordon | J5: CORDON 10 CM | L5: =SUMIFS(F34:F42,A34:A42,J5) -> 997920
A6: TEJIDO | B6: Rollo C14x 2mt x 2 1/2" | C6: un | D6: =$C$2/10 -> 18 | E6: ='PRECIOS TODOS'!B7 -> 99041.404 | F6: =D6*E6 -> 1782745.3 | G6: =F6 -> 1782745.3 | I6: Hilos de Pua | J6: 0 | L6: =G20*J6 -> 0
A7: TEJIDO | B7: Rollo C14x 2mt x 2" | C7: un | D7: =$C$2/10 -> 18 | E7: ='PRECIOS TODOS'!B8 -> 115550.16 | F7: =D7*E7 -> 2079902.9 | G7: =F7 -> 2079902.9 | I7: Total | J7: =SUM(L3:L6)+M4 -> 8974302.1
A8: TEJIDO | B8: Rollo C12x 2mt x 3 1/2" | C8: un | D8: =$C$2/10 -> 18 | E8: ='PRECIOS TODOS'!B9 -> 100199.13 | F8: =D8*E8 -> 1803584.4 | G8: =F8 -> 1803584.4 | I8: Precio x mtl | J8: =J7/C2 -> 49857.234
A9: TEJIDO | B9: Rollo C12x 2mt x 3" | C9: un | D9: =$C$2/10 -> 18 | E9: ='PRECIOS TODOS'!B10 -> 110796.8 | F9: =D9*E9 -> 1994342.3 | G9: =F9 -> 1994342.3 | I9: Precio x mtl < 50 ml (cercos de menos de 50metros lineales) | J9: =J8*130% -> 64814.404
A10: TEJIDO | B10: Rollo C12x 2mt x 2 1/2" | C10: un | D10: =$C$2/10 -> 18 | E10: ='PRECIOS TODOS'!B12 -> 152463.87 | F10: =D10*E10 -> 2744349.7 | G10: =F10 -> 2744349.7
A11: TEJIDO | B11: Rollo C12x 2mt x 2" | C11: un | D11: =$C$2/10 -> 18 | E11: ='PRECIOS TODOS'!B13 -> 169451.3 | F11: =D11*E11 -> 3050123.5 | G11: =F11 -> 3050123.5
A12: ACCESORIOS | B12: Ganchos c/tuerca y arandela x 8" | C12: un | D12: 48 | E12: ='PRECIOS TODOS'!B185 -> 12337.5 | F12: =D12*E12 -> 592200 | G12: =SUM(F12:F19) -> 3629531.6
A13: ACCESORIOS | B13: Planchuela de 2mt | C13: un | D13: 12 | E13: ='PRECIOS TODOS'!B190 -> 5456.4533 | F13: =D13*E13 -> 65477.44
A14: ACCESORIOS | B14: Torniquete mini cincado | C14: un | D14: 6 | E14: ='PRECIOS TODOS'!B181 -> 12337.5 | F14: =D14*E14 -> 74025
A15: ACCESORIOS | B15: Esparragos | C15: un | D15: 6 | E15: ='PRECIOS TODOS'!B194 -> 1330 | F15: =D15*E15 -> 7980
A16: ACCESORIOS | B16: Alambre de Alta Resistencia (4 hilos) | C16: mt | D16: 720 | E16: ='PRECIOS TODOS'!B188 -> 3105.48 | F16: =D16*E16 -> 2235945.6
A17: ACCESORIOS | B17: Clavos | C17: kg | D17: 2 | E17: ='PRECIOS TODOS'!B194 -> 1330 | F17: =D17*E17 -> 2660
A18: ACCESORIOS | B18: Alambre negro | C18: kg | D18: 8 | E18: ='PRECIOS TODOS'!B192 -> 844.2 | F18: =D18*E18 -> 6753.6
A19: ACCESORIOS | B19: Transporte | C19: un | D19: 180 | E19: ='PRECIOS TODOS'!B205 -> 3580.5 | F19: =D19*E19 -> 644490
A20: PUA | B20: Alambre de puas (1 hilo) | C20: mt | D20: =C2 -> 180 | E20: ='PRECIOS TODOS'!B191*90% -> 1168.02 | F20: =D20*E20 -> 210243.6 | G20: =SUM(F20:F21) -> 284268.6
A21: PUA | B21: Torniquete mini cincado | C21: un | D21: 6 | E21: ='PRECIOS TODOS'!B181 -> 12337.5 | F21: =D21*E21 -> 74025
A22: POSTES OLIMP | B22: Postes Esquineros 3.05mt | C22: un | D22: 4 | E22: ='PRECIOS TODOS'!B137 -> 35000 | F22: =D22*E22 -> 140000 | G22: =SUM(F22:F25) -> 1450000
A23: POSTES OLIMP | B23: Postes Refuerzos 3.05mt | C23: un | D23: 2 | E23: ='PRECIOS TODOS'!B138 -> 31250 | F23: =D23*E23 -> 62500
A24: POSTES OLIMP | B24: Postes Intermedios 3.05mt | C24: un | D24: 34 | E24: ='PRECIOS TODOS'!B139 -> 28750 | F24: =D24*E24 -> 977500
A25: POSTES OLIMP | B25: Puntales 2.40mt | C25: un | D25: 12 | E25: ='PRECIOS TODOS'!B140 -> 22500 | F25: =D25*E25 -> 270000
A26: POSTES P DIAMANTE | B26: Postes Esquineros 2.8mt | C26: un | D26: 4 | E26: ='PRECIOS TODOS'!B150 -> 31250 | F26: =D26*E26 -> 125000 | G26: =SUM(F26:F29) -> 1300000
A27: POSTES P DIAMANTE | B27: Postes Refuerzos 3.05mt | C27: un | D27: 2 | E27: ='PRECIOS TODOS'!B151 -> 27500 | F27: =D27*E27 -> 55000
A28: POSTES P DIAMANTE | B28: Postes Intermedios 2.8mt | C28: un | D28: 34 | E28: ='PRECIOS TODOS'!B152 -> 25000 | F28: =D28*E28 -> 850000
A29: POSTES P DIAMANTE | B29: Puntales 2.40mt | C29: un | D29: 12 | E29: ='PRECIOS TODOS'!B140 -> 22500 | F29: =D29*E29 -> 270000
A30: POSTE EUCALIPTO | B30: Postes Esquineros 2.8mt | C30: un | D30: 4 | E30: ='PRECIOS TODOS'!B163 -> 22500 | F30: =D30*E30 -> 90000 | G30: =SUM(F30:F33) -> 1110000
A31: POSTE EUCALIPTO | B31: Postes Refuerzos 3.05mt | C31: un | D31: 2 | E31: ='PRECIOS TODOS'!B163 -> 22500 | F31: =D31*E31 -> 45000
A32: POSTE EUCALIPTO | B32: Postes Intermedios 2.8mt | C32: un | D32: 34 | E32: ='PRECIOS TODOS'!B163 -> 22500 | F32: =D32*E32 -> 765000
A33: POSTE EUCALIPTO | B33: Puntales 2mt | C33: un | D33: 12 | E33: ='PRECIOS TODOS'!B176 -> 17500 | F33: =D33*E33 -> 210000
A34: CORDON 20 CM | B34: Arena | C34: m3 | D34: 8 | E34: ='PRECIOS TODOS'!B202 -> 30240 | F34: =+D34*E34 -> 241920 | G34: =SUM(F34:F36) -> 1164380
A35: CORDON 20 CM | B35: Ripio | C35: m3 | D35: 8 | E35: ='PRECIOS TODOS'!B196 -> 43820 | F35: =+D35*E35 -> 350560
A36: CORDON 20 CM | B36: Cemento | C36: 50 kg | D36: 50 | E36: ='PRECIOS TODOS'!B204 -> 11438 | F36: =+D36*E36 -> 571900
A37: CORDON 15 CM | B37: Arena | C37: m3 | D37: =(D34/4)*3 -> 6 | E37: ='PRECIOS TODOS'!B202 -> 30240 | F37: =+D37*E37 -> 181440 | G37: =SUM(F37:F39) -> 791805
A38: CORDON 15 CM | B38: Ripio | C38: m3 | D38: =(D35/4)*3 -> 6 | E38: ='PRECIOS TODOS'!B202 -> 30240 | F38: =+D38*E38 -> 181440
A39: CORDON 15 CM | B39: Cemento | C39: 50 kg | D39: =(D36/4)*3 -> 37.5 | E39: ='PRECIOS TODOS'!B204 -> 11438 | F39: =+D39*E39 -> 428925
A40: CORDON 10 CM | B40: Arena | C40: m3 | D40: =(D34/2) -> 4 | E40: ='PRECIOS TODOS'!B202 -> 30240 | F40: =+D40*E40 -> 120960 | G40: =SUM(F40:F42) -> 997920
...

Sheet Cerco con rollo de  1.8mt
B1: DIMENSION | C1: 60x30
B2: MTL | C2: 180 | I2: Presupuesto | L2: Calculos Auxiliares
A3: Grupo | B3: Accesorios | C3: Un. Medida | D3: Cantidad | E3: Precio x Unidad | F3: Sub Total | G3: TOTAL | I3: Tipo Tejido | J3: Rollo C12x 1.8mt x 2 1/2" | L3: =SUMIFS(G4:G11,B4:B11,J3) -> 2438776.3 | M3: Instalacion
A4: TEJIDO | B4: Rollo C14x 1.8mt x 3 1/2" | C4: un | D4: =$C$2/10 -> 18 | E4: ='PRECIOS TODOS'!B20 -> 60190.724 | F4: =D4*E4 -> 1083433 | G4: =F4 -> 1083433 | I4: Tipo Poste | J4: POSTES OLIMP | L4: =SUMIFS(F22:F33,A22:A33,J4) -> 1306000 | M4: =G12+G43 -> 5012390
A5: TEJIDO | B5: Rollo C14x 1.8mt x 3" | C5: un | D5: =$C$2/10 -> 18 | E5: ='PRECIOS TODOS'!B21 -> 75252.32 | F5: =D5*E5 -> 1354541.8 | G5: =F5 -> 1354541.8 | I5: Tipo Cordon | J5: CORDON 15 CM | L5: =SUMIFS(F34:F42,A34:A42,J5) -> 791805
A6: TEJIDO | B6: Rollo C14x 1.8mt x 2 1/2" | C6: un | D6: =$C$2/10 -> 18 | E6: ='PRECIOS TODOS'!B23 -> 87798.084 | F6: =D6*E6 -> 1580365.5 | G6: =F6 -> 1580365.5 | I6: Hilos de Pua | J6: 3 | L6: =G20*J6 -> 852805.8
A7: TEJIDO | B7: Rollo C14x 1.8mt x 2" | C7: un | D7: =$C$2/10 -> 18 | E7: ='PRECIOS TODOS'!B24 -> 103583.26 | F7: =D7*E7 -> 1864498.7 | G7: =F7 -> 1864498.7 | I7: Total | J7: =SUM(L3:L6)+M4 -> 10401777
A8: TEJIDO | B8: Rollo C12x 1.8mt x 3 1/2" | C8: un | D8: =$C$2/10 -> 18 | E8: ='PRECIOS TODOS'!B25 -> 90325.048 | F8: =D8*E8 -> 1625850.9 | G8: =F8 -> 1625850.9 | I8: Precio x mtl | J8: =J7/C2 -> 57787.651
A9: TEJIDO | B9: Rollo C12x 1.8mt x 3" | C9: un | D9: =$C$2/10 -> 18 | E9: ='PRECIOS TODOS'!B26 -> 99475.552 | F9: =D9*E9 -> 1790559.9 | G9: =F9 -> 1790559.9 | I9: Precio x mtl < 50 ml (cercos de menos de 50metros lineales) | J9: =J8*130% -> 75123.946
A10: TEJIDO | B10: Rollo C12x 1.8mt x 2 1/2" | C10: un | D10: =$C$2/10 -> 18 | E10: ='PRECIOS TODOS'!B28 -> 135487.57 | F10: =D10*E10 -> 2438776.3 | G10: =F10 -> 2438776.3
A11: TEJIDO | B11: Rollo C12x 1.8mt x 2" | C11: un | D11: =$C$2/10 -> 18 | E11: ='PRECIOS TODOS'!B29 -> 163662.66 | F11: =D11*E11 -> 2945928 | G11: =F11 -> 2945928
A12: ACCESORIOS | B12: Ganchos c/tuerca y arandela x 8" | C12: un | D12: =D13*3 -> 36 | E12: ='PRECIOS TODOS'!B185 -> 12337.5 | F12: =D12*E12 -> 444150 | G12: =SUM(F12:F19) -> 2953550
A13: ACCESORIOS | B13: Planchuela de 2mt | C13: un | D13: 12 | E13: ='PRECIOS TODOS'!B190 -> 5456.4533 | F13: =D13*E13 -> 65477.44
A14: ACCESORIOS | B14: Torniquete mini cincado | C14: un | D14: 6 | E14: ='PRECIOS TODOS'!B181 -> 12337.5 | F14: =D14*E14 -> 74025
A15: ACCESORIOS | B15: Esparragos | C15: un | D15: 6 | E15: ='PRECIOS TODOS'!B194 -> 1330 | F15: =D15*E15 -> 7980
A16: ACCESORIOS | B16: Alambre de Alta Resistencia (3 hilos) | C16: mt | D16: 550 | E16: ='PRECIOS TODOS'!B188 -> 3105.48 | F16: =D16*E16 -> 1708014
A17: ACCESORIOS | B17: Clavos | C17: kg | D17: 2 | E17: ='PRECIOS TODOS'!B194 -> 1330 | F17: =D17*E17 -> 2660
A18: ACCESORIOS | B18: Alambre negro | C18: kg | D18: 8 | E18: ='PRECIOS TODOS'!B192 -> 844.2 | F18: =D18*E18 -> 6753.6
A19: ACCESORIOS | B19: Transporte | C19: un | D19: 180 | E19: ='PRECIOS TODOS'!B205 -> 3580.5 | F19: =D19*E19 -> 644490
A20: PUA | B20: Alambre de puas (1 hilo) | C20: mt | D20: =C2 -> 180 | E20: ='PRECIOS TODOS'!B191*90% -> 1168.02 | F20: =D20*E20 -> 210243.6 | G20: =SUM(F20:F21) -> 284268.6
A21: PUA | B21: Torniquete mini cincado | C21: un | D21: 6 | E21: ='PRECIOS TODOS'!B181 -> 12337.5 | F21: =D21*E21 -> 74025
A22: POSTES OLIMP | B22: Postes Esquineros 2.8mt | C22: un | D22: 4 | E22: ='PRECIOS TODOS'!B143 -> 32000 | F22: =D22*E22 -> 128000 | G22: =SUM(F22:F25) -> 1306000
A23: POSTES OLIMP | B23: Postes Refuerzos 2.8mt | C23: un | D23: 2 | E23: ='PRECIOS TODOS'!B144 -> 29000 | F23: =D23*E23 -> 58000
A24: POSTES OLIMP | B24: Postes Intermedios 2.8mt | C24: un | D24: 34 | E24: ='PRECIOS TODOS'!B145 -> 25000 | F24: =D24*E24 -> 850000
A25: POSTES OLIMP | B25: Puntales 2.40mt | C25: un | D25: 12 | E25: ='PRECIOS TODOS'!B140 -> 22500 | F25: =D25*E25 -> 270000
A26: POSTES P DIAMANTE | B26: Postes Esquineros 2.8mt | C26: un | D26: 4 | E26: ='PRECIOS TODOS'!B161 -> 33750 | F26: =D26*E26 -> 135000 | G26: =SUM(F26:F29) -> 1535000
A27: POSTES P DIAMANTE | B27: Postes Refuerzos 2,8 mt | C27: un | D27: 2 | E27: ='PRECIOS TODOS'!B161 -> 33750 | F27: =D27*E27 -> 67500
A28: POSTES P DIAMANTE | B28: Postes Intermedios 2.8mt | C28: un | D28: 34 | E28: ='PRECIOS TODOS'!B162 -> 31250 | F28: =D28*E28 -> 1062500
A29: POSTES P DIAMANTE | B29: Puntales 2.40mt | C29: un | D29: 12 | E29: ='PRECIOS TODOS'!B140 -> 22500 | F29: =D29*E29 -> 270000
A30: POSTE EUCALIPTO | B30: Postes Esquineros 2.8mt | C30: un | D30: 4 | E30: ='PRECIOS TODOS'!B163 -> 22500 | F30: =D30*E30 -> 90000 | G30: =SUM(F30:F33) -> 1170000
A31: POSTE EUCALIPTO | B31: Postes Refuerzos 2,8 mt | C31: un | D31: 2 | E31: ='PRECIOS TODOS'!B163 -> 22500 | F31: =D31*E31 -> 45000
A32: POSTE EUCALIPTO | B32: Postes Intermedios 2.8mt | C32: un | D32: 34 | E32: ='PRECIOS TODOS'!B163 -> 22500 | F32: =D32*E32 -> 765000
A33: POSTE EUCALIPTO | B33: Puntales 2.40mt | C33: un | D33: 12 | E33: ='PRECIOS TODOS'!B163 -> 22500 | F33: =D33*E33 -> 270000
A34: CORDON 20 CM | B34: Arena | C34: m3 | D34: 8 | E34: ='PRECIOS TODOS'!B202 -> 30240 | F34: =+D34*E34 -> 241920 | G34: =SUM(F34:F36) -> 1164380
A35: CORDON 20 CM | B35: Ripio | C35: m3 | D35: 8 | E35: ='PRECIOS TODOS'!B196 -> 43820 | F35: =+D35*E35 -> 350560
A36: CORDON 20 CM | B36: Cemento | C36: 50 kg | D36: 50 | E36: ='PRECIOS TODOS'!B204 -> 11438 | F36: =+D36*E36 -> 571900
A37: CORDON 15 CM | B37: Arena | C37: m3 | D37: =(D34/4)*3 -> 6 | E37: ='PRECIOS TODOS'!B202 -> 30240 | F37: =+D37*E37 -> 181440 | G37: =SUM(F37:F39) -> 791805
A38: CORDON 15 CM | B38: Ripio | C38: m3 | D38: =(D35/4)*3 -> 6 | E38: ='PRECIOS TODOS'!B202 -> 30240 | F38: =+D38*E38 -> 181440
A39: CORDON 15 CM | B39: Cemento | C39: 50 kg | D39: =(D36/4)*3 -> 37.5 | E39: ='PRECIOS TODOS'!B204 -> 11438 | F39: =+D39*E39 -> 428925
A40: CORDON 10 CM | B40: Arena | C40: m3 | D40: =(D34/2) -> 4 | E40: ='PRECIOS TODOS'!B202 -> 30240 | F40: =+D40*E40 -> 120960 | G40: =SUM(F40:F42) -> 997920
...

Sheet Cerco con rollo de  1.5mt
B1: DIMENSION | C1: 60x30
B2: MTL | C2: 180 | I2: Presupuesto | L2: Calculos Auxiliares
A3: Grupo | B3: Accesorios | C3: Un. Medida | D3: Cantidad | E3: Precio x Unidad | F3: Sub Total | G3: TOTAL | I3: Tipo Tejido | J3: Rollo C14x 1.5mt x 3 1/2" | L3: =SUMIFS(G4:G11,B4:B11,J3) -> 912111.55 | M3: Instalacion
A4: TEJIDO | B4: Rollo C14x 1.5mt x 3 1/2" | C4: un | D4: =$C$2/10 -> 18 | E4: ='PRECIOS TODOS'!B36 -> 50672.864 | F4: =D4*E4 -> 912111.55 | G4: =F4 -> 912111.55 | I4: Tipo Poste | J4: POSTE EUCALIPTO | L4: =SUMIFS(F22:F33,A22:A33,J4) -> 1048050 | M4: =G12+G43 -> 5012390
A5: TEJIDO | B5: Rollo C14x 1.5mt x 3" | C5: un | D5: =$C$2/10 -> 18 | E5: ='PRECIOS TODOS'!B37 -> 62272.408 | F5: =D5*E5 -> 1120903.3 | G5: =F5 -> 1120903.3 | I5: Tipo Cordon | J5: CORDON 10 CM | L5: =SUMIFS(F34:F42,A34:A42,J5) -> 527870
A6: TEJIDO | B6: Rollo C14x 1.5mt x 2 1/2" | C6: un | D6: =$C$2/10 -> 18 | E6: ='PRECIOS TODOS'!B39 -> 72012.908 | F6: =D6*E6 -> 1296232.3 | G6: =F6 -> 1296232.3 | I6: Hilos de Pua | J6: 0 | L6: =G20*J6 -> 0
A7: TEJIDO | B7: Rollo C14x 1.5mt x 2" | C7: un | D7: =$C$2/10 -> 18 | E7: ='PRECIOS TODOS'!B40 -> 87798.084 | F7: =D7*E7 -> 1580365.5 | G7: =F7 -> 1580365.5 | I7: Total | J7: =SUM(L3:L6)+M4 -> 7500421.6
A8: TEJIDO | B8: Rollo C12x 1.5mt x 3 1/2" | C8: un | D8: =$C$2/10 -> 18 | E8: ='PRECIOS TODOS'!B41 -> 76231.936 | F8: =D8*E8 -> 1372174.8 | G8: =F8 -> 1372174.8 | I8: Precio x mtl | J8: =J7/C2 -> 41669.009
A9: TEJIDO | B9: Rollo C12x 1.5mt x 3" | C9: un | D9: =$C$2/10 -> 18 | E9: ='PRECIOS TODOS'!B42 -> 85382.44 | F9: =D9*E9 -> 1536883.9 | G9: =F9 -> 1536883.9 | I9: Precio x mtl < 50 ml (cercos de menos de 50metros lineales) | J9: =J8*130% -> 54169.711
A10: TEJIDO | B10: Rollo C12x 1.5mt x 2 1/2" | C10: un | D10: =$C$2/10 -> 18 | E10: ='PRECIOS TODOS'!B44 -> 115004.69 | F10: =D10*E10 -> 2070084.5 | G10: =F10 -> 2070084.5
A11: TEJIDO | B11: Rollo C12x 1.5mt x 2" | C11: un | D11: =$C$2/10 -> 18 | E11: ='PRECIOS TODOS'!B45 -> 121394.46 | F11: =D11*E11 -> 2185100.3 | G11: =F11 -> 2185100.3
A12: ACCESORIOS | B12: Ganchos c/tuerca y arandela x 8" | C12: un | D12: =D13*3 -> 36 | E12: ='PRECIOS TODOS'!B185 -> 12337.5 | F12: =D12*E12 -> 444150 | G12: =SUM(F12:F19) -> 2953550
A13: ACCESORIOS | B13: Planchuela de 2mt | C13: un | D13: 12 | E13: ='PRECIOS TODOS'!B190 -> 5456.4533 | F13: =D13*E13 -> 65477.44
A14: ACCESORIOS | B14: Torniquete mini cincado | C14: un | D14: 6 | E14: ='PRECIOS TODOS'!B181 -> 12337.5 | F14: =D14*E14 -> 74025
A15: ACCESORIOS | B15: Esparragos | C15: un | D15: 6 | E15: ='PRECIOS TODOS'!B194 -> 1330 | F15: =D15*E15 -> 7980
A16: ACCESORIOS | B16: Alambre de Alta Resistencia (3 hilos) | C16: mt | D16: 550 | E16: ='PRECIOS TODOS'!B188 -> 3105.48 | F16: =D16*E16 -> 1708014
A17: ACCESORIOS | B17: Clavos | C17: kg | D17: 2 | E17: ='PRECIOS TODOS'!B194 -> 1330 | F17: =D17*E17 -> 2660
A18: ACCESORIOS | B18: Alambre negro | C18: kg | D18: 8 | E18: ='PRECIOS TODOS'!B192 -> 844.2 | F18: =D18*E18 -> 6753.6
A19: ACCESORIOS | B19: Transporte | C19: un | D19: 180 | E19: ='PRECIOS TODOS'!B205 -> 3580.5 | F19: =D19*E19 -> 644490
A20: PUA | B20: Alambre de puas (1 hilo) | C20: mt | D20: =C2 -> 180 | E20: ='PRECIOS TODOS'!B191*90% -> 1168.02 | F20: =D20*E20 -> 210243.6 | G20: =SUM(F20:F21) -> 284268.6
A21: PUA | B21: Torniquete mini cincado | C21: un | D21: 6 | E21: ='PRECIOS TODOS'!B181 -> 12337.5 | F21: =D21*E21 -> 74025
A22: POSTES OLIMP | B22: Postes Esquineros 2.8mt | C22: un | D22: 4 | E22: ='PRECIOS TODOS'!B143 -> 32000 | F22: =D22*E22 -> 128000 | G22: =SUM(F22:F25) -> 1306000
A23: POSTES OLIMP | B23: Postes Refuerzos 2.8mt | C23: un | D23: 2 | E23: ='PRECIOS TODOS'!B144 -> 29000 | F23: =D23*E23 -> 58000
A24: POSTES OLIMP | B24: Postes Intermedios 2.8mt | C24: un | D24: 34 | E24: ='PRECIOS TODOS'!B145 -> 25000 | F24: =D24*E24 -> 850000
A25: POSTES OLIMP | B25: Puntales 2.40mt | C25: un | D25: 12 | E25: ='PRECIOS TODOS'!B140 -> 22500 | F25: =D25*E25 -> 270000
A26: POSTES P DIAMANTE | B26: Postes Esquineros 2.8mt | C26: un | D26: 4 | E26: ='PRECIOS TODOS'!B166 -> 33750 | F26: =D26*E26 -> 135000 | G26: =SUM(F26:F29) -> 1535000
A27: POSTES P DIAMANTE | B27: Postes Refuerzos 3.05mt | C27: un | D27: 2 | E27: ='PRECIOS TODOS'!B166 -> 33750 | F27: =D27*E27 -> 67500
A28: POSTES P DIAMANTE | B28: Postes Intermedios 2.8mt | C28: un | D28: 34 | E28: ='PRECIOS TODOS'!B150 -> 31250 | F28: =D28*E28 -> 1062500
A29: POSTES P DIAMANTE | B29: Puntales 2.40mt | C29: un | D29: 12 | E29: ='PRECIOS TODOS'!B140 -> 22500 | F29: =D29*E29 -> 270000
A30: POSTE EUCALIPTO | B30: Postes Esquineros 2.8mt | C30: un | D30: 4 | E30: ='PRECIOS TODOS'!B163 -> 22500 | F30: =D30*E30 -> 90000 | G30: =SUM(F30:F33) -> 1048050
A31: POSTE EUCALIPTO | B31: Postes Refuerzos 3.05mt | C31: un | D31: 2 | E31: ='PRECIOS TODOS'!B163 -> 22500 | F31: =D31*E31 -> 45000
A32: POSTE EUCALIPTO | B32: Postes Intermedios 2.8mt | C32: un | D32: 34 | E32: ='PRECIOS TODOS'!B163 -> 22500 | F32: =D32*E32 -> 765000
A33: POSTE EUCALIPTO | B33: Puntales 2.40mt | C33: un | D33: 12 | E33: ='PRECIOS TODOS'!B181 -> 12337.5 | F33: =D33*E33 -> 148050
A34: CORDON 20 CM | B34: Arena | C34: m3 | D34: 8 | E34: ='PRECIOS TODOS'!B202 -> 30240 | F34: =+D34*E34 -> 241920 | G34: =SUM(F34:F36) -> 1164380
A35: CORDON 20 CM | B35: Ripio | C35: m3 | D35: 8 | E35: ='PRECIOS TODOS'!B196 -> 43820 | F35: =+D35*E35 -> 350560
A36: CORDON 20 CM | B36: Cemento | C36: 50 kg | D36: 50 | E36: ='PRECIOS TODOS'!B204 -> 11438 | F36: =+D36*E36 -> 571900
A37: CORDON 15 CM | B37: Arena | C37: m3 | D37: =(D34/4)*3 -> 6 | E37: ='PRECIOS TODOS'!B202 -> 30240 | F37: =+D37*E37 -> 181440 | G37: =SUM(F37:F39) -> 791805
A38: CORDON 15 CM | B38: Ripio | C38: m3 | D38: =(D35/4)*3 -> 6 | E38: ='PRECIOS TODOS'!B202 -> 30240 | F38: =+D38*E38 -> 181440
A39: CORDON 15 CM | B39: Cemento | C39: 50 kg | D39: =(D36/4)*3 -> 37.5 | E39: ='PRECIOS TODOS'!B204 -> 11438 | F39: =+D39*E39 -> 428925
A40: CORDON 10 CM | B40: Arena | C40: m3 | D40: =(D34/2) -> 4 | E40: ='PRECIOS TODOS'!B202 -> 30240 | F40: =+D40*E40 -> 120960 | G40: =SUM(F40:F42) -> 527870
...

Sheet Cerco con rollo de 1.2mt
B1: DIMENSION | C1: 60x30
B2: MTL | C2: 180 | I2: Presupuesto | L2: Calculos Auxiliares
A3: Grupo | B3: Accesorios | C3: Un. Medida | D3: Cantidad | E3: Precio x Unidad | F3: Sub Total | G3: TOTAL | I3: Tipo Tejido | J3: Rollo C14x 1.2mt x 3 1/2" | L3: =SUMIFS(G4:G11,B4:B11,J3) -> 721980 | M3: Instalacion
A4: TEJIDO | B4: Rollo C14x 1.2mt x 3 1/2" | C4: un | D4: =$C$2/10 -> 18 | E4: ='PRECIOS TODOS'!B52 -> 40110 | F4: =D4*E4 -> 721980 | G4: =F4 -> 721980 | I4: Tipo Poste | J4: POSTE EUCALIPTO | L4: =SUMIFS(F22:F33,A22:A33,J4) -> 1048050 | M4: =G12+G43 -> 4422348.8
A5: TEJIDO | B5: Rollo C14x 1.2mt x 3" | C5: un | D5: =$C$2/10 -> 18 | E5: ='PRECIOS TODOS'!B53 -> 47950 | F5: =D5*E5 -> 863100 | G5: =F5 -> 863100 | I5: Tipo Cordon | J5: CORDON 10 CM | L5: =SUMIFS(F34:F42,A34:A42,J5) -> 997920
A6: TEJIDO | B6: Rollo C14x 1.2mt x 2 1/2" | C6: un | D6: =$C$2/10 -> 18 | E6: ='PRECIOS TODOS'!B55 -> 55240 | F6: =D6*E6 -> 994320 | G6: =F6 -> 994320 | I6: Hilos de Pua | J6: 0 | L6: =G20*J6 -> 0
A7: TEJIDO | B7: Rollo C14x 1.2mt x 2" | C7: un | D7: =$C$2/10 -> 18 | E7: ='PRECIOS TODOS'!B56 -> 65340 | F7: =D7*E7 -> 1176120 | G7: =F7 -> 1176120 | I7: Total | J7: =SUM(L3:L6)+M4 -> 7190298.8
A8: TEJIDO | B8: Rollo C12x 1.2mt x 3 1/2" | C8: un | D8: =$C$2/10 -> 18 | E8: ='PRECIOS TODOS'!B57 -> 55820 | F8: =D8*E8 -> 1004760 | G8: =F8 -> 1004760 | I8: Precio x mtl | J8: =J7/C2 -> 39946.105
A9: TEJIDO | B9: Rollo C12x 1.2mt x 3" | C9: un | D9: =$C$2/10 -> 18 | E9: ='PRECIOS TODOS'!B58 -> 64040 | F9: =D9*E9 -> 1152720 | G9: =F9 -> 1152720 | I9: Precio x mtl < 50 ml (cercos de menos de 50metros lineales) | J9: =J8*130% -> 51929.936
A10: TEJIDO | B10: Rollo C12x 1.2mt x 2 1/2" | C10: un | D10: =$C$2/10 -> 18 | E10: ='PRECIOS TODOS'!B60 -> 81790 | F10: =D10*E10 -> 1472220 | G10: =F10 -> 1472220
A11: TEJIDO | B11: Rollo C12x 1.2mt x 2" | C11: un | D11: =$C$2/10 -> 18 | E11: ='PRECIOS TODOS'!B61 -> 91310 | F11: =D11*E11 -> 1643580 | G11: =F11 -> 1643580
A12: ACCESORIOS | B12: Ganchos c/tuerca y arandela x 8" | C12: un | D12: =D13*3 -> 36 | E12: ='PRECIOS TODOS'!B185 -> 12337.5 | F12: =D12*E12 -> 444150 | G12: =SUM(F12:F19) -> 2363508.8
A13: ACCESORIOS | B13: Planchuela de 2mt | C13: un | D13: 12 | E13: ='PRECIOS TODOS'!B190 -> 5456.4533 | F13: =D13*E13 -> 65477.44
A14: ACCESORIOS | B14: Torniquete mini cincado | C14: un | D14: 6 | E14: ='PRECIOS TODOS'!B181 -> 12337.5 | F14: =D14*E14 -> 74025
A15: ACCESORIOS | B15: Esparragos | C15: un | D15: 6 | E15: ='PRECIOS TODOS'!B194 -> 1330 | F15: =D15*E15 -> 7980
A16: ACCESORIOS | B16: Alambre de Alta Resistencia (3 hilos) | C16: mt | D16: 360 | E16: ='PRECIOS TODOS'!B188 -> 3105.48 | F16: =D16*E16 -> 1117972.8
A17: ACCESORIOS | B17: Clavos | C17: kg | D17: 2 | E17: ='PRECIOS TODOS'!B194 -> 1330 | F17: =D17*E17 -> 2660
A18: ACCESORIOS | B18: Alambre negro | C18: kg | D18: 8 | E18: ='PRECIOS TODOS'!B192 -> 844.2 | F18: =D18*E18 -> 6753.6
A19: ACCESORIOS | B19: Transporte | C19: un | D19: 180 | E19: ='PRECIOS TODOS'!B205 -> 3580.5 | F19: =D19*E19 -> 644490
A20: PUA | B20: Alambre de puas (1 hilo) | C20: mt | D20: =C2 -> 180 | E20: ='PRECIOS TODOS'!B191*90% -> 1168.02 | F20: =D20*E20 -> 210243.6 | G20: =SUM(F20:F21) -> 284268.6
A21: PUA | B21: Torniquete mini cincado | C21: un | D21: 6 | E21: ='PRECIOS TODOS'!B181 -> 12337.5 | F21: =D21*E21 -> 74025
A22: POSTES OLIMP | B22: Postes Esquineros 2.8mt | C22: un | D22: 4 | E22: ='PRECIOS TODOS'!B143 -> 32000 | F22: =D22*E22 -> 128000 | G22: =SUM(F22:F25) -> 1306000
A23: POSTES OLIMP | B23: Postes Refuerzos 2.8mt | C23: un | D23: 2 | E23: ='PRECIOS TODOS'!B144 -> 29000 | F23: =D23*E23 -> 58000
A24: POSTES OLIMP | B24: Postes Intermedios 2.8mt | C24: un | D24: 34 | E24: ='PRECIOS TODOS'!B145 -> 25000 | F24: =D24*E24 -> 850000
A25: POSTES OLIMP | B25: Puntales 2.40mt | C25: un | D25: 12 | E25: ='PRECIOS TODOS'!B140 -> 22500 | F25: =D25*E25 -> 270000
A26: POSTES P DIAMANTE | B26: Postes Esquineros 2.8mt | C26: un | D26: 4 | E26: ='PRECIOS TODOS'!B166 -> 33750 | F26: =D26*E26 -> 135000 | G26: =SUM(F26:F29) -> 1535000
A27: POSTES P DIAMANTE | B27: Postes Refuerzos 3.05mt | C27: un | D27: 2 | E27: ='PRECIOS TODOS'!B166 -> 33750 | F27: =D27*E27 -> 67500
A28: POSTES P DIAMANTE | B28: Postes Intermedios 2.8mt | C28: un | D28: 34 | E28: ='PRECIOS TODOS'!B150 -> 31250 | F28: =D28*E28 -> 1062500
A29: POSTES P DIAMANTE | B29: Puntales 2.40mt | C29: un | D29: 12 | E29: ='PRECIOS TODOS'!B140 -> 22500 | F29: =D29*E29 -> 270000
A30: POSTE EUCALIPTO | B30: Postes Esquineros 2.8mt | C30: un | D30: 4 | E30: ='PRECIOS TODOS'!B163 -> 22500 | F30: =D30*E30 -> 90000 | G30: =SUM(F30:F33) -> 1048050
A31: POSTE EUCALIPTO | B31: Postes Refuerzos 3.05mt | C31: un | D31: 2 | E31: ='PRECIOS TODOS'!B163 -> 22500 | F31: =D31*E31 -> 45000
A32: POSTE EUCALIPTO | B32: Postes Intermedios 2.8mt | C32: un | D32: 34 | E32: ='PRECIOS TODOS'!B163 -> 22500 | F32: =D32*E32 -> 765000
A33: POSTE EUCALIPTO | B33: Puntales 2.40mt | C33: un | D33: 12 | E33: ='PRECIOS TODOS'!B181 -> 12337.5 | F33: =D33*E33 -> 148050
A34: CORDON 20 CM | B34: Arena | C34: m3 | D34: 8 | E34: ='PRECIOS TODOS'!B202 -> 30240 | F34: =+D34*E34 -> 241920 | G34: =SUM(F34:F36) -> 1164380
A35: CORDON 20 CM | B35: Ripio | C35: m3 | D35: 8 | E35: ='PRECIOS TODOS'!B196 -> 43820 | F35: =+D35*E35 -> 350560
A36: CORDON 20 CM | B36: Cemento | C36: 50 kg | D36: 50 | E36: ='PRECIOS TODOS'!B204 -> 11438 | F36: =+D36*E36 -> 571900
A37: CORDON 15 CM | B37: Arena | C37: m3 | D37: =(D34/4)*3 -> 6 | E37: ='PRECIOS TODOS'!B202 -> 30240 | F37: =+D37*E37 -> 181440 | G37: =SUM(F37:F39) -> 791805
A38: CORDON 15 CM | B38: Ripio | C38: m3 | D38: =(D35/4)*3 -> 6 | E38: ='PRECIOS TODOS'!B202 -> 30240 | F38: =+D38*E38 -> 181440
A39: CORDON 15 CM | B39: Cemento | C39: 50 kg | D39: =(D36/4)*3 -> 37.5 | E39: ='PRECIOS TODOS'!B204 -> 11438 | F39: =+D39*E39 -> 428925
A40: CORDON 10 CM | B40: Arena | C40: m3 | D40: =(D34/2) -> 4 | E40: ='PRECIOS TODOS'!B202 -> 30240 | F40: =+D40*E40 -> 120960 | G40: =SUM(F40:F42) -> 997920
...
