Workbook

Sheet Resumen de precios
A1: =TODAY() -> 45943 | I1: OFERTAS EN EFECTIVO - TEJIDO ROMBOIDAL
A2: *Rollo x 10mts. Tejido romb. x 2,00 mt*
A3: *CALIDAD ECONOMICA* | I3: Tejido Romboidal de 2 mt Alto Calibre Nº 14 con rombos de 3 1/2" | J3: =B4 -> 65445.028
A4: -Cal 14 c/rombos de 3 ½'' | B4: =D4*92% -> 65445.028 | C4: (Contado) | D4: ='Tejidos romboidales'!K2*121% -> 71135.9 | E4: (Lista) | F4: =D4*105% -> 74692.695 | G4: (Tarjeta) | I4: Tejido Romboidal de 1.8 mt Alto Calibre Nº 14 con rombos de 3 1/2" | J4: =B20 -> 60190.724
A5: -Cal 14 c/rombos de 3'' | B5: =D5*92% -> 80651.34 | C5: (Contado) | D5: ='Tejidos romboidales'!K7*121% -> 87664.5 | E5: (Lista) | F5: =D5*105% -> 92047.725 | G5: (Tarjeta) | I5: Tejido Romboidal de 1.5 mt Alto Calibre Nº 14 con rombos de 3 1/2" | J5: =B36 -> 50672.864
A6: *CALIDAD STANDARD* | I6: Tejido Romboidal de 1.2 mt Alto Calibre Nº 14 con rombos de 3 1/2" | J6: =B52 -> 40110
A7: -Cal 14 c/rombos de 2 ½" | B7: =D7*92% -> 99041.404 | C7: (Contado) | D7: ='Tejidos romboidales'!K12*121% -> 107653.7 | E7: (Lista) | F7: =D7*105% -> 113036.38 | G7: (Tarjeta) | I7: Tejido Romboidal de 1 mt Alto Calibre Nº 14 con rombos de 3 1/2" | J7: =B68 -> 32510
A8: -Cal 14 c/rombos de 2'' | B8: =D8*92% -> 115550.16 | C8: (Contado) | D8: ='Tejidos romboidales'!K17*121% -> 125598 | E8: (Lista) | F8: =D8*105% -> 131877.9 | G8: (Tarjeta)
A9: -Cal 12 c/rombos de 3 ½'' | B9: =D9*92% -> 100199.13 | C9: (Contado) | D9: ='Tejidos romboidales'!K22*121% -> 108912.1 | E9: (Lista) | F9: =D9*105% -> 114357.71 | G9: (Tarjeta)
A10: -Cal 12 c/rombos de 3'' | B10: =D10*92% -> 110796.8 | C10: (Contado) | D10: ='Tejidos romboidales'!K27*121% -> 120431.3 | E10: (Lista) | F10: =D10*105% -> 126452.87 | G10: (Tarjeta)
A11: *CALIDAD REFORZADA*
A12: -Cal 12 c/rombos de 2 ½" | B12: =D12*92% -> 152463.87 | C12: (Contado) | D12: ='Tejidos romboidales'!K32*121% -> 165721.6 | E12: (Lista) | F12: =D12*105% -> 174007.68 | G12: (Tarjeta)
A13: -Cal 12 c/rombos de 2'' | B13: =D13*92% -> 169451.3 | C13: (Contado) | D13: ='Tejidos romboidales'!K37*121% -> 184186.2 | E13: (Lista) | F13: =D13*105% -> 193395.51 | G13: (Tarjeta)
A15: La resistencia del rollo está sujeta al calibre del alambre y el tamaño del rombo
A18: *Rollo x 10mts. Tejido romb. x 1,80 mt*
A19: *CALIDAD ECONOMICA*
A20: -Cal 14 c/rombos de 3 ½'' | B20: =D20*92% -> 60190.724 | C20: (Contado) | D20: ='Tejidos romboidales'!K3*121% -> 65424.7 | E20: (Lista) | F20: =D20*105% -> 68695.935 | G20: (Tarjeta)
A21: -Cal 14 c/rombos de 3'' | B21: =D21*92% -> 75252.32 | C21: (Contado) | D21: ='Tejidos romboidales'!K8*121% -> 81796 | E21: (Lista) | F21: =D21*105% -> 85885.8 | G21: (Tarjeta)
A22: *CALIDAD STANDARD*
A23: -Cal 14 c/rombos de 2 ½" | B23: =D23*92% -> 87798.084 | C23: (Contado) | D23: ='Tejidos romboidales'!K13*121% -> 95432.7 | E23: (Lista) | F23: =D23*105% -> 100204.34 | G23: (Tarjeta)
A24: -Cal 14 c/rombos de 2'' | B24: =D24*92% -> 103583.26 | C24: (Contado) | D24: ='Tejidos romboidales'!K18*121% -> 112590.5 | E24: (Lista) | F24: =D24*105% -> 118220.03 | G24: (Tarjeta)
A25: -Cal 12 c/rombos de 3 ½'' | B25: =D25*92% -> 90325.048 | C25: (Contado) | D25: ='Tejidos romboidales'!K23*121% -> 98179.4 | E25: (Lista) | F25: =D25*105% -> 103088.37 | G25: (Tarjeta)
A26: -Cal 12 c/rombos de 3'' | B26: =D26*92% -> 99475.552 | C26: (Contado) | D26: ='Tejidos romboidales'!K28*121% -> 108125.6 | E26: (Lista) | F26: =D26*105% -> 113531.88 | G26: (Tarjeta)
A27: *CALIDAD REFORZADA*
A28: -Cal 12 c/rombos de 2 ½" | B28: =D28*92% -> 135487.57 | C28: (Contado) | D28: ='Tejidos romboidales'!K33*121% -> 147269.1 | E28: (Lista) | F28: =D28*105% -> 154632.56 | G28: (Tarjeta)
A29: -Cal 12 c/rombos de 2'' | B29: =D29*92% -> 163662.66 | C29: (Contado) | D29: ='Tejidos romboidales'!K38*121% -> 177894.2 | E29: (Lista) | F29: =D29*105% -> 186788.91 | G29: (Tarjeta)
A31: La resistencia del rollo está sujeta al calibre del alambre y el tamaño del rombo
A34: *Rollo x 10mts. Tejido romb. x 1,50 mt*
A35: *CALIDAD ECONOMICA*
A36: -Cal 14 c/rombos de 3 ½'' | B36: =D36*92% -> 50672.864 | C36: (Contado) | D36: ='Tejidos romboidales'!K4*121% -> 55079.2 | E36: (Lista) | F36: =D36*105% -> 57833.16 | G36: (Tarjeta)
A37: -Cal 14 c/rombos de 3'' | B37: =D37*92% -> 62272.408 | C37: (Contado) | D37: ='Tejidos romboidales'!K9*121% -> 67687.4 | E37: (Lista) | F37: =D37*105% -> 71071.77 | G37: (Tarjeta)
A38: *CALIDAD STANDARD*
A39: -Cal 14 c/rombos de 2 ½" | B39: =D39*92% -> 72012.908 | C39: (Contado) | D39: ='Tejidos romboidales'!K14*121% -> 78274.9 | E39: (Lista) | F39: =D39*105% -> 82188.645 | G39: (Tarjeta)
A40: -Cal 14 c/rombos de 2'' | B40: =D40*92% -> 87798.084 | C40: (Contado) | D40: ='Tejidos romboidales'!K19*121% -> 95432.7 | E40: (Lista) | F40: =D40*105% -> 100204.34 | G40: (Tarjeta)
A41: -Cal 12 c/rombos de 3 ½'' | B41: =D41*92% -> 76231.936 | C41: (Contado) | D41: ='Tejidos romboidales'!K24*121% -> 82860.8 | E41: (Lista) | F41: =D41*105% -> 87003.84 | G41: (Tarjeta)
A42: -Cal 12 c/rombos de 3'' | B42: =D42*92% -> 85382.44 | C42: (Contado) | D42: ='Tejidos romboidales'!K29*121% -> 92807 | E42: (Lista) | F42: =D42*105% -> 97447.35 | G42: (Tarjeta)
A43: *CALIDAD REFORZADA*
A44: -Cal 12 c/rombos de 2 ½" | B44: =D44*92% -> 115004.69 | C44: (Contado) | D44: ='Tejidos romboidales'!K34*121% -> 125005.1 | E44: (Lista) | F44: =D44*105% -> 131255.36 | G44: (Tarjeta)
A45: -Cal 12 c/rombos de 2'' | B45: =D45*92% -> 121394.46 | C45: (Contado) | D45: ='Tejidos romboidales'!K39*121% -> 131950.5 | E45: (Lista) | F45: =D45*105% -> 138548.02 | G45: (Tarjeta)
A47: La resistencia del rollo está sujeta al calibre del alambre y el tamaño del rombo
...

Sheet Tejidos romboidales
A1: Codigo | B1: Descripcion | C1: Calibre'' | D1: Separacion'' | E1: Altura mt | F1: Peso por rollo(kg) | G1: Precio por kg | H1: Mano de obra | I1: Precio de costo | J1: Precio Venta + | K1: 0.3 | L1: Precio de la competencia
A2: ="RC"&C2&"x"&D2&"x"&E2 -> RC14x3,5x2 | B2: ="Calibre " & C2 & " Alt " &E2& "m" & " con rombos de " &D2 -> Calibre 14 Alt 2m con rombos de 3,5 | C2: 14 | D2: 3.5 | E2: 2 | F2: 12 | G2: =Articulos!$E$4 -> 3135.77 | H2: 7600 | I2: =F2*G2+H2 -> 45229.24 | J2: =I2*$K$1 -> 13568.772 | K2: =(I2+J2)-MOD((I2+J2),10) -> 58790
A3: ="RC"&C3&"x"&D3&"x"&E3 -> RC14x3,5x1,8 | B3: ="Calibre " & C3 & " Alt " &E3& "m" & " con rombos de " &D3 -> Calibre 14 Alt 1,8m con rombos de 3,5 | C3: 14 | D3: 3.5 | E3: 1.8 | F3: 11 | G3: =Articulos!$E$4 -> 3135.77 | H3: 7100 | I3: =F3*G3+H3 -> 41593.47 | J3: =I3*$K$1 -> 12478.041 | K3: =(I3+J3)-MOD((I3+J3),10) -> 54070
A4: ="RC"&C4&"x"&D4&"x"&E4 -> RC14x3,5x1,5 | B4: ="Calibre " & C4 & " Alt " &E4& "m" & " con rombos de " &D4 -> Calibre 14 Alt 1,5m con rombos de 3,5 | C4: 14 | D4: 3.5 | E4: 1.5 | F4: 9 | G4: =Articulos!$E$4 -> 3135.77 | H4: 6800 | I4: =F4*G4+H4 -> 35021.93 | J4: =I4*$K$1 -> 10506.579 | K4: =(I4+J4)-MOD((I4+J4),10) -> 45520
A5: ="RC"&C5&"x"&D5&"x"&E5 -> RC14x3,5x1,2 | B5: ="Calibre " & C5 & " Alt " &E5& "m" & " con rombos de " &D5 -> Calibre 14 Alt 1,2m con rombos de 3,5 | C5: 14 | D5: 3.5 | E5: 1.2 | F5: 7.8 | G5: =Articulos!$E$4 -> 3135.77 | H5: 6400 | I5: =F5*G5+H5 -> 30859.006 | J5: =I5*$K$1 -> 9257.7018 | K5: =(I5+J5)-MOD((I5+J5),10) -> 40110
A6: ="RC"&C6&"x"&D6&"x"&E6 -> RC14x3,5x1 | B6: ="Calibre " & C6 & " Alt " &E6& "m" & " con rombos de " &D6 -> Calibre 14 Alt 1m con rombos de 3,5 | C6: 14 | D6: 3.5 | E6: 1 | F6: 6 | G6: =Articulos!$E$4 -> 3135.77 | H6: 6200 | I6: =F6*G6+H6 -> 25014.62 | J6: =I6*$K$1 -> 7504.386 | K6: =(I6+J6)-MOD((I6+J6),10) -> 32510
A7: ="RC"&C7&"x"&D7&"x"&E7 -> RC14x3x2 | B7: ="Calibre " & C7 & " Alt " &E7& "m" & " con rombos de " &D7 -> Calibre 14 Alt 2m con rombos de 3 | C7: 14 | D7: 3 | E7: 2 | F7: 15 | G7: =Articulos!$E$4 -> 3135.77 | H7: 8700 | I7: =F7*G7+H7 -> 55736.55 | J7: =I7*$K$1 -> 16720.965 | K7: =(I7+J7)-MOD((I7+J7),10) -> 72450 | L7: 61000
A8: ="RC"&C8&"x"&D8&"x"&E8 -> RC14x3x1,8 | B8: ="Calibre " & C8 & " Alt " &E8& "m" & " con rombos de " &D8 -> Calibre 14 Alt 1,8m con rombos de 3 | C8: 14 | D8: 3 | E8: 1.8 | F8: 14 | G8: =Articulos!$E$4 -> 3135.77 | H8: 8100 | I8: =F8*G8+H8 -> 52000.78 | J8: =I8*$K$1 -> 15600.234 | K8: =(I8+J8)-MOD((I8+J8),10) -> 67600 | L8: 55000
A9: ="RC"&C9&"x"&D9&"x"&E9 -> RC14x3x1,5 | B9: ="Calibre " & C9 & " Alt " &E9& "m" & " con rombos de " &D9 -> Calibre 14 Alt 1,5m con rombos de 3 | C9: 14 | D9: 3 | E9: 1.5 | F9: 11.3 | G9: =Articulos!$E$4 -> 3135.77 | H9: 7600 | I9: =F9*G9+H9 -> 43034.201 | J9: =I9*$K$1 -> 12910.26 | K9: =(I9+J9)-MOD((I9+J9),10) -> 55940 | L9: 47500
A10: ="RC"&C10&"x"&D10&"x"&E10 -> RC14x3x1,2 | B10: ="Calibre " & C10 & " Alt " &E10& "m" & " con rombos de " &D10 -> Calibre 14 Alt 1,2m con rombos de 3 | C10: 14 | D10: 3 | E10: 1.2 | F10: 9.5 | G10: =Articulos!$E$4 -> 3135.77 | H10: 7100 | I10: =F10*G10+H10 -> 36889.815 | J10: =I10*$K$1 -> 11066.944 | K10: =(I10+J10)-MOD((I10+J10),10) -> 47950
A11: ="RC"&C11&"x"&D11&"x"&E11 -> RC14x3x1 | B11: ="Calibre " & C11 & " Alt " &E11& "m" & " con rombos de " &D11 -> Calibre 14 Alt 1m con rombos de 3 | C11: 14 | D11: 3 | E11: 1 | F11: 8 | G11: =Articulos!$E$4 -> 3135.77 | H11: 6900 | I11: =F11*G11+H11 -> 31986.16 | J11: =I11*$K$1 -> 9595.848 | K11: =(I11+J11)-MOD((I11+J11),10) -> 41580
A12: ="RC"&C12&"x"&D12&"x"&E12 -> RC14x2,5x2 | B12: ="Calibre " & C12 & " Alt " &E12& "m" & " con rombos de " &D12 -> Calibre 14 Alt 2m con rombos de 2,5 | C12: 14 | D12: 2.5 | E12: 2 | F12: 18 | G12: =Articulos!$E$4 -> 3135.77 | H12: 12000 | I12: =F12*G12+H12 -> 68443.86 | J12: =I12*$K$1 -> 20533.158 | K12: =(I12+J12)-MOD((I12+J12),10) -> 88970 | L12: 72000
A13: ="RC"&C13&"x"&D13&"x"&E13 -> RC14x2,5x1,8 | B13: ="Calibre " & C13 & " Alt " &E13& "m" & " con rombos de " &D13 -> Calibre 14 Alt 1,8m con rombos de 2,5 | C13: 14 | D13: 2.5 | E13: 1.8 | F13: 16 | G13: =Articulos!$E$4 -> 3135.77 | H13: 10500 | I13: =F13*G13+H13 -> 60672.32 | J13: =I13*$K$1 -> 18201.696 | K13: =(I13+J13)-MOD((I13+J13),10) -> 78870 | L13: 64000
A14: ="RC"&C14&"x"&D14&"x"&E14 -> RC14x2,5x1,5 | B14: ="Calibre " & C14 & " Alt " &E14& "m" & " con rombos de " &D14 -> Calibre 14 Alt 1,5m con rombos de 2,5 | C14: 14 | D14: 2.5 | E14: 1.5 | F14: 13 | G14: =Articulos!$E$4 -> 3135.77 | H14: 9000 | I14: =F14*G14+H14 -> 49765.01 | J14: =I14*$K$1 -> 14929.503 | K14: =(I14+J14)-MOD((I14+J14),10) -> 64690 | L14: 54000
A15: ="RC"&C15&"x"&D15&"x"&E15 -> RC14x2,5x1,2 | B15: ="Calibre " & C15 & " Alt " &E15& "m" & " con rombos de " &D15 -> Calibre 14 Alt 1,2m con rombos de 2,5 | C15: 14 | D15: 2.5 | E15: 1.2 | F15: 11 | G15: =Articulos!$E$4 -> 3135.77 | H15: 8000 | I15: =F15*G15+H15 -> 42493.47 | J15: =I15*$K$1 -> 12748.041 | K15: =(I15+J15)-MOD((I15+J15),10) -> 55240
A16: ="RC"&C16&"x"&D16&"x"&E16 -> RC14x2,5x1 | B16: ="Calibre " & C16 & " Alt " &E16& "m" & " con rombos de " &D16 -> Calibre 14 Alt 1m con rombos de 2,5 | C16: 14 | D16: 2.5 | E16: 1 | F16: 9 | G16: =Articulos!$E$4 -> 3135.77 | H16: 7800 | I16: =F16*G16+H16 -> 36021.93 | J16: =I16*$K$1 -> 10806.579 | K16: =(I16+J16)-MOD((I16+J16),10) -> 46820
A17: ="RC"&C17&"x"&D17&"x"&E17 -> RC14x2x2 | B17: ="Calibre " & C17 & " Alt " &E17& "m" & " con rombos de " &D17 -> Calibre 14 Alt 2m con rombos de 2 | C17: 14 | D17: 2 | E17: 2 | F17: 21 | G17: =Articulos!$E$4 -> 3135.77 | H17: 14000 | I17: =F17*G17+H17 -> 79851.17 | J17: =I17*$K$1 -> 23955.351 | K17: =(I17+J17)-MOD((I17+J17),10) -> 103800 | L17: 84500
A18: ="RC"&C18&"x"&D18&"x"&E18 -> RC14x2x1,8 | B18: ="Calibre " & C18 & " Alt " &E18& "m" & " con rombos de " &D18 -> Calibre 14 Alt 1,8m con rombos de 2 | C18: 14 | D18: 2 | E18: 1.8 | F18: 19 | G18: =Articulos!$E$4 -> 3135.77 | H18: 12000 | I18: =F18*G18+H18 -> 71579.63 | J18: =I18*$K$1 -> 21473.889 | K18: =(I18+J18)-MOD((I18+J18),10) -> 93050 | L18: 79000
A19: ="RC"&C19&"x"&D19&"x"&E19 -> RC14x2x1,5 | B19: ="Calibre " & C19 & " Alt " &E19& "m" & " con rombos de " &D19 -> Calibre 14 Alt 1,5m con rombos de 2 | C19: 14 | D19: 2 | E19: 1.5 | F19: 16 | G19: =Articulos!$E$4 -> 3135.77 | H19: 10500 | I19: =F19*G19+H19 -> 60672.32 | J19: =I19*$K$1 -> 18201.696 | K19: =(I19+J19)-MOD((I19+J19),10) -> 78870 | L19: 65000
A20: ="RC"&C20&"x"&D20&"x"&E20 -> RC14x2x1,2 | B20: ="Calibre " & C20 & " Alt " &E20& "m" & " con rombos de " &D20 -> Calibre 14 Alt 1,2m con rombos de 2 | C20: 14 | D20: 2 | E20: 1.2 | F20: 13 | G20: =Articulos!$E$4 -> 3135.77 | H20: 9500 | I20: =F20*G20+H20 -> 50265.01 | J20: =I20*$K$1 -> 15079.503 | K20: =(I20+J20)-MOD((I20+J20),10) -> 65340
A21: ="RC"&C21&"x"&D21&"x"&E21 -> RC14x2x1 | B21: ="Calibre " & C21 & " Alt " &E21& "m" & " con rombos de " &D21 -> Calibre 14 Alt 1m con rombos de 2 | C21: 14 | D21: 2 | E21: 1 | F21: 11 | G21: =Articulos!$E$4 -> 3135.77 | H21: 9300 | I21: =F21*G21+H21 -> 43793.47 | J21: =I21*$K$1 -> 13138.041 | K21: =(I21+J21)-MOD((I21+J21),10) -> 56930
A22: ="RC"&C22&"x"&D22&"x"&E22 -> RC12x3,5x2 | B22: ="Calibre " & C22 & " Alt " &E22& "m" & " con rombos de " &D22 -> Calibre 12 Alt 2m con rombos de 3,5 | C22: 12 | D22: 3.5 | E22: 2 | F22: 20 | G22: =Articulos!$E$2 -> 2912 | H22: 11000 | I22: =F22*G22+H22 -> 69240 | J22: =I22*$K$1 -> 20772 | K22: =(I22+J22)-MOD((I22+J22),10) -> 90010
A23: ="RC"&C23&"x"&D23&"x"&E23 -> RC12x3,5x1,8 | B23: ="Calibre " & C23 & " Alt " &E23& "m" & " con rombos de " &D23 -> Calibre 12 Alt 1,8m con rombos de 3,5 | C23: 12 | D23: 3.5 | E23: 1.8 | F23: 18 | G23: =Articulos!$E$2 -> 2912 | H23: 10000 | I23: =F23*G23+H23 -> 62416 | J23: =I23*$K$1 -> 18724.8 | K23: =(I23+J23)-MOD((I23+J23),10) -> 81140
A24: ="RC"&C24&"x"&D24&"x"&E24 -> RC12x3,5x1,5 | B24: ="Calibre " & C24 & " Alt " &E24& "m" & " con rombos de " &D24 -> Calibre 12 Alt 1,5m con rombos de 3,5 | C24: 12 | D24: 3.5 | E24: 1.5 | F24: 15 | G24: =Articulos!$E$2 -> 2912 | H24: 9000 | I24: =F24*G24+H24 -> 52680 | J24: =I24*$K$1 -> 15804 | K24: =(I24+J24)-MOD((I24+J24),10) -> 68480
A25: ="RC"&C25&"x"&D25&"x"&E25 -> RC12x3,5x1,2 | B25: ="Calibre " & C25 & " Alt " &E25& "m" & " con rombos de " &D25 -> Calibre 12 Alt 1,2m con rombos de 3,5 | C25: 12 | D25: 3.5 | E25: 1.2 | F25: 12 | G25: =Articulos!$E$2 -> 2912 | H25: 8000 | I25: =F25*G25+H25 -> 42944 | J25: =I25*$K$1 -> 12883.2 | K25: =(I25+J25)-MOD((I25+J25),10) -> 55820
A26: ="RC"&C26&"x"&D26&"x"&E26 -> RC12x3,5x1 | B26: ="Calibre " & C26 & " Alt " &E26& "m" & " con rombos de " &D26 -> Calibre 12 Alt 1m con rombos de 3,5 | C26: 12 | D26: 3.5 | E26: 1 | F26: 10 | G26: =Articulos!$E$2 -> 2912 | H26: 7000 | I26: =F26*G26+H26 -> 36120 | J26: =I26*$K$1 -> 10836 | K26: =(I26+J26)-MOD((I26+J26),10) -> 46950
A27: ="RC"&C27&"x"&D27&"x"&E27 -> RC12x3x2 | B27: ="Calibre " & C27 & " Alt " &E27& "m" & " con rombos de " &D27 -> Calibre 12 Alt 2m con rombos de 3 | C27: 12 | D27: 3 | E27: 2 | F27: 22 | G27: =Articulos!$E$2 -> 2912 | H27: 12500 | I27: =F27*G27+H27 -> 76564 | J27: =I27*$K$1 -> 22969.2 | K27: =(I27+J27)-MOD((I27+J27),10) -> 99530
A28: ="RC"&C28&"x"&D28&"x"&E28 -> RC12x3x1,8 | B28: ="Calibre " & C28 & " Alt " &E28& "m" & " con rombos de " &D28 -> Calibre 12 Alt 1,8m con rombos de 3 | C28: 12 | D28: 3 | E28: 1.8 | F28: 20 | G28: =Articulos!$E$2 -> 2912 | H28: 10500 | I28: =F28*G28+H28 -> 68740 | J28: =I28*$K$1 -> 20622 | K28: =(I28+J28)-MOD((I28+J28),10) -> 89360
A29: ="RC"&C29&"x"&D29&"x"&E29 -> RC12x3x1,5 | B29: ="Calibre " & C29 & " Alt " &E29& "m" & " con rombos de " &D29 -> Calibre 12 Alt 1,5m con rombos de 3 | C29: 12 | D29: 3 | E29: 1.5 | F29: 17 | G29: =Articulos!$E$2 -> 2912 | H29: 9500 | I29: =F29*G29+H29 -> 59004 | J29: =I29*$K$1 -> 17701.2 | K29: =(I29+J29)-MOD((I29+J29),10) -> 76700
A30: ="RC"&C30&"x"&D30&"x"&E30 -> RC12x3x1,2 | B30: ="Calibre " & C30 & " Alt " &E30& "m" & " con rombos de " &D30 -> Calibre 12 Alt 1,2m con rombos de 3 | C30: 12 | D30: 3 | E30: 1.2 | F30: 14 | G30: =Articulos!$E$2 -> 2912 | H30: 8500 | I30: =F30*G30+H30 -> 49268 | J30: =I30*$K$1 -> 14780.4 | K30: =(I30+J30)-MOD((I30+J30),10) -> 64040
A31: ="RC"&C31&"x"&D31&"x"&E31 -> RC12x3x1 | B31: ="Calibre " & C31 & " Alt " &E31& "m" & " con rombos de " &D31 -> Calibre 12 Alt 1m con rombos de 3 | C31: 12 | D31: 3 | E31: 1 | F31: 12 | G31: =Articulos!$E$2 -> 2912 | H31: 7500 | I31: =F31*G31+H31 -> 42444 | J31: =I31*$K$1 -> 12733.2 | K31: =(I31+J31)-MOD((I31+J31),10) -> 55170
A32: ="RC"&C32&"x"&D32&"x"&E32 -> RC12x2,5x2 | B32: ="Calibre " & C32 & " Alt " &E32& "m" & " con rombos de " &D32 -> Calibre 12 Alt 2m con rombos de 2,5 | C32: 12 | D32: 2.5 | E32: 2 | F32: 30 | G32: =Articulos!$E$2 -> 2912 | H32: 18000 | I32: =F32*G32+H32 -> 105360 | J32: =I32*$K$1 -> 31608 | K32: =(I32+J32)-MOD((I32+J32),10) -> 136960
A33: ="RC"&C33&"x"&D33&"x"&E33 -> RC12x2,5x1,8 | B33: ="Calibre " & C33 & " Alt " &E33& "m" & " con rombos de " &D33 -> Calibre 12 Alt 1,8m con rombos de 2,5 | C33: 12 | D33: 2.5 | E33: 1.8 | F33: 27 | G33: =Articulos!$E$2 -> 2912 | H33: 15000 | I33: =F33*G33+H33 -> 93624 | J33: =I33*$K$1 -> 28087.2 | K33: =(I33+J33)-MOD((I33+J33),10) -> 121710
... A37: ="RC"&C37&"x"&D37&"x"&E37 -> RC12x2x2 | B37: ="Calibre " & C37 & " Alt " &E37& "m" & " con rombos de " &D37 -> Calibre 12 Alt 2m con rombos de 2 | C37: 12 | D37: 2 | E37: 2 | F37: 33 | G37: =Articulos!$E$2 -> 2912 | H37: 21000 | I37: =F37*G37+H37 -> 117096 | J37: =I37*$K$1 -> 35128.8 | K37: =(I37+J37)-MOD((I37+J37),10) -> 152220
A38: ="RC"&C38&"x"&D38&"x"&E38 -> RC12x2x1,8 | B38: ="Calibre " & C38 & " Alt " &E38& "m" & " con rombos de " &D38 -> Calibre 12 Alt 1,8m con rombos de 2 | C38: 12 | D38: 2 | E38: 1.8 | F38: 29 | G38: =Articulos!$E$2 -> 2912 | H38: 17000 | I38: =F37*G38+H38 -> 113096 | J38: =I38*$K$1 -> 33928.8 | K38: =(I38+J38)-MOD((I38+J38),10) -> 147020
A39: ="RC"&C39&"x"&D39&"x"&E39 -> RC12x2x1,5 | B39: ="Calibre " & C39 & " Alt " &E39& "m" & " con rombos de " &D39 -> Calibre 12 Alt 1,5m con rombos de 2 | C39: 12 | D39: 2 | E39: 1.5 | F39: 24 | G39: =Articulos!$E$2 -> 2912 | H39: 14000 | I39: =F39*G39+H39 -> 83888 | J39: =I39*$K$1 -> 25166.4 | K39: =(I39+J39)-MOD((I39+J39),10) -> 109050
A40: ="RC"&C40&"x"&D40&"x"&E40 -> RC12x2x1,2 | B40: ="Calibre " & C40 & " Alt " &E40& "m" & " con rombos de " &D40 -> Calibre 12 Alt 1,2m con rombos de 2 | C40: 12 | D40: 2 | E40: 1.2 | F40: 20 | G40: =Articulos!$E$2 -> 2912 | H40: 12000 | I40: =F40*G40+H40 -> 70240 | J40: =I40*$K$1 -> 21072 | K40: =(I40+J40)-MOD((I40+J40),10) -> 91310
A41: ="RC"&C41&"x"&D41&"x"&E41 -> RC12x2x1 | B41: ="Calibre " & C41 & " Alt " &E41& "m" & " con rombos de " &D41 -> Calibre 12 Alt 1m con rombos de 2 | C41: 12 | D41: 2 | E41: 1 | F41: 16 | G41: =Articulos!$E$2 -> 2912 | H41: 11000 | I41: =F41*G41+H41 -> 57592 | J41: =I41*$K$1 -> 17277.6 | K41: =(I41+J41)-MOD((I41+J41),10) -> 74860

Sheet Articulos
A1: Elemento | B1: Unidad | C1: Dimensiones | D1: Cantidad Estandar | E1: Precio Costo(neto + impuestos) | F1: Precio Venta (Lista) | G1: Precio Efectivo/Transf. | H1: Precio Tarjeta | I1: cheq 45 dias | J1: cheq 60 dias | K1: cheq 90 dias
A2: Alambre Galvanizado Calibre 12 | B2: kg | C2: 12' | E2: 2912 | F2: =(E2*140%)*121% -> 4932.928 | G2: =F2*92% -> 4538.2938 | H2: =F2*105% -> 5179.5744 | I2: =F2 -> 4932.928 | J2: =F2*105% -> 5179.5744 | K2: =F2*110% -> 5426.2208
A3: Alambre Galvanizado Calibre 13 | B3: kg | C3: 14' | E3: 2912 | F3: =(E3*140%)*121% -> 4932.928 | G3: =F3*92% -> 4538.2938 | H3: =F3*105% -> 5179.5744 | I3: =F3 -> 4932.928 | J3: =F3*105% -> 5179.5744 | K3: =F3*110% -> 5426.2208
A4: Alambre Galvanizado Calibre 14 | B4: kg | C4: 14' | E4: 3135.77 | F4: =(E4*140%)*121% -> 5311.9944 | G4: =F4*92% -> 4887.0348 | H4: =F4*105% -> 5577.5941 | I4: =F4 -> 5311.9944 | J4: =F4*105% -> 5577.5941 | K4: =F4*110% -> 5843.1938
A5: Varilla roscada | B5: u | C5: 3/8" | E5: 5785.124 | F5: =(E5*140%)*121% -> 9800 | G5: =F5*92% -> 9016 | H5: =F5*105% -> 10290 | I5: =F5 -> 9800 | J5: =F5*105% -> 10290 | K5: =F5*110% -> 10780
A6: Planchuela 7/8 x 3/16" | B6: mts | C6: 7/8 x 3/16 | D6: 6 | E6: 9663.1405 | F6: =(E6*140%)*121% -> 16369.36 | G6: =F6*92% -> 15059.811 | H6: =F6*105% -> 17187.828 | I6: =F6 -> 16369.36 | J6: =F6*105% -> 17187.828 | K6: =F6*110% -> 18006.296
A7: Planchuela 7/8 x 3/16" 2mt | B7: u | C7: 7/8 x 3/16 | D7: 1 | E7: 3221.0468 | F7: =(E7*140%)*121% -> 5456.4533 | G7: =F7*92% -> 5019.9371 | H7: =F7*105% -> 5729.276 | I7: =F7 -> 5456.4533 | J7: =F7*105% -> 5729.276 | K7: =F7*110% -> 6002.0987
A8: Torniqueta Galvanizada Micro | B8: u | C8: - | E8: 923.96694 | F8: =(E8*140%)*121% -> 1565.2 | G8: =F8*92% -> 1439.984 | H8: =F8*105% -> 1643.46 | I8: =F8 -> 1565.2 | J8: =F8*105% -> 1643.46 | K8: =F8*110% -> 1721.72
A9: Torniqueta Galvanizada Mini N 5 | B9: u | C9: - | E9: 1833.2231 | F9: =(E9*140%)*121% -> 3105.48 | G9: =F9*92% -> 2857.0416 | H9: =F9*105% -> 3260.754 | I9: =F9 -> 3105.48 | J9: =F9*105% -> 3260.754 | K9: =F9*110% -> 3416.028
A10: Torniqueta Galvanizada N 7 | B10: u | C10: - | E10: 2355.3719 | F10: =(E10*140%)*121% -> 3990 | G10: =F10*92% -> 3670.8 | H10: =F10*105% -> 4189.5 | I10: =F10 -> 3990 | J10: =F10*105% -> 4189.5 | K10: =F10*110% -> 4389
A11: Ganchos Galvanizados 3/8" x 10" | B11: u | C11: 3/8" | E11: 766.1157 | F11: =(E11*140%)*121% -> 1297.8 | G11: =F11*92% -> 1193.976 | H11: =F11*105% -> 1362.69 | I11: =F11 -> 1297.8 | J11: =F11*105% -> 1362.69 | K11: =F11*110% -> 1427.58
A12: Ganchos Galvanizados 3/8" x 8'' | B12: u | C12: 3/8" | E12: 498.34711 | F12: =(E12*140%)*121% -> 844.2 | G12: =F12*92% -> 776.664 | H12: =F12*105% -> 886.41 | I12: =F12 -> 844.2 | J12: =F12*105% -> 886.41 | K12: =F12*110% -> 928.62
A13: Ganchos Galvanizados 3/8" x 7'' | B13: u | C13: 3/8" | E13: 517.35537 | F13: =(E13*140%)*121% -> 876.4 | G13: =F13*92% -> 806.288 | H13: =F13*105% -> 920.22 | I13: =F13 -> 876.4 | J13: =F13*105% -> 920.22 | K13: =F13*110% -> 964.04
A14: Esparragos Galvanizados de 3/8" x 10" | B14: u | C14: 3/8" | E14: 785.12397 | F14: =(E14*140%)*121% -> 1330 | G14: =F14*92% -> 1223.6 | H14: =F14*105% -> 1396.5 | I14: =F14 -> 1330 | J14: =F14*105% -> 1396.5 | K14: =F14*110% -> 1463
A15: Alambre de Púas x rollo de 100mts | B15: u | C15: - | D15: 100 | E15: 25867.769 | F15: =(E15*140%)*121% -> 43820 | G15: =F15*92% -> 40314.4 | H15: =F15*105% -> 46011 | I15: =F15 -> 43820 | J15: =F15*105% -> 46011 | K15: =F15*110% -> 48202
A16: Alambre de Púas x rollo de 500mts | B16: u | C16: - | D16: 500 | E16: 97768.595 | F16: =(E16*140%)*121% -> 165620 | G16: =F16*92% -> 152370.4 | H16: =F16*105% -> 173901 | I16: =F16 -> 165620 | J16: =F16*105% -> 173901 | K16: =F16*110% -> 182182
A17: Alambre de Púas x mt | B17: mts | C17: - | D17: 1 | E17: 258.67769 | F17: =(E17*140%)*121% -> 438.2 | G17: =F17*92% -> 403.144 | H17: =F17*105% -> 460.11 | I17: =F17 -> 438.2 | J17: =F17*105% -> 460.11 | K17: =F17*110% -> 482.02
A18: Alambre Acindar A/R | B18: mts | C18: 17/15 | D18: 1000 | E18: 146405.31 | F18: =(E18*140%)*121% -> 248010.6 | G18: =F18*92% -> 228169.75 | H18: =F18*105% -> 260411.13 | I18: =F18 -> 248010.6 | J18: =F18*105% -> 260411.13 | K18: =F18*110% -> 272811.66
A19: Alambre Acindar A/R | B19: mts | C19: 16/14 | D19: 1000 | E19: 135600.83 | F19: =(E19*140%)*121% -> 229707.8 | G19: =F19*92% -> 211331.18 | H19: =F19*105% -> 241193.19 | I19: =F19 -> 229707.8 | J19: =F19*105% -> 241193.19 | K19: =F19*110% -> 252678.58
A20: Alambre Acindar A/R | B20: mts | C20: 17/15 | D20: 1 | E20: 146.40531 | F20: =(E20*140%)*121% -> 248.0106 | G20: =F20*92% -> 228.16975 | H20: =F20*105% -> 260.41113 | I20: =F20 -> 248.0106 | J20: =F20*105% -> 260.41113 | K20: =F20*110% -> 272.81166
A21: Alambre Acindar A/R | B21: mts | C21: 16/14 | D21: 1 | E21: 135.60083 | F21: =(E21*140%)*121% -> 229.7078 | G21: =F21*92% -> 211.33118 | H21: =F21*105% -> 241.19319 | I21: =F21 -> 229.7078 | J21: =F21*105% -> 241.19319 | K21: =F21*110% -> 252.67858
A22: Alambre Negro 14 | B22: kg | C22: - | E22: 2571.5537 | F22: =(E22*140%)*121% -> 4356.212 | G22: =F22*92% -> 4007.715 | H22: =F22*105% -> 4574.0226 | I22: =F22 -> 4356.212 | J22: =F22*105% -> 4574.0226 | K22: =F22*110% -> 4791.8332
A23: Alambre Negro 16 | B23: kg | C23: - | E23: 2637.4298 | F23: =(E23*140%)*121% -> 4467.806 | G23: =F23*92% -> 4110.3815 | H23: =F23*105% -> 4691.1963 | I23: =F23 -> 4467.806 | J23: =F23*105% -> 4691.1963 | K23: =F23*110% -> 4914.5866
A24: Alambre Negro 8 | B24: kg | E24: 2538.0992 | F24: =(E24*140%)*121% -> 4299.54 | G24: =F24*92% -> 3955.5768 | H24: =F24*105% -> 4514.517 | I24: =F24 -> 4299.54 | J24: =F24*105% -> 4514.517 | K24: =F24*110% -> 4729.494
A25: Rollo C14 2 mt x 15mtx x 2 1/2" | B25: u | C25: 2 | E25: 9616.0407 | F25: =(E25*140%)*121% -> 16289.573 | G25: =F25*92% -> 14986.407 | H25: =F25*105% -> 17104.052 | I25: =F25 -> 16289.573 | J25: =F25*105% -> 17104.052 | K25: =F25*110% -> 17918.53
A26: Rollo C14 2 mt x 10mtx x 2 1/2" | B26: u | C26: 2 | E26: 6410.6938 | F26: =(E26*140%)*121% -> 10859.715 | G26: =F26*92% -> 9990.9381 | H26: =F26*105% -> 11402.701 | I26: =F26 -> 10859.715 | J26: =F26*105% -> 11402.701 | K26: =F26*110% -> 11945.687
A27: Rollo C14 2 mt x 15mtx x 2 " | B27: u | C27: 2 | E27: 12017.36 | F27: =(E27*140%)*121% -> 20357.408 | G27: =F27*92% -> 18728.816 | H27: =F27*105% -> 21375.279 | I27: =F27 -> 20357.408 | J27: =F27*105% -> 21375.279 | K27: =F27*110% -> 22393.149
A28: Rollo C14 2 mt x 10mtx x 2 " | B28: u | C28: 2 | E28: 8011.5735 | F28: =(E28*140%)*121% -> 13571.606 | G28: =F28*92% -> 12485.877 | H28: =F28*105% -> 14250.186 | I28: =F28 -> 13571.606 | J28: =F28*105% -> 14250.186 | K28: =F28*110% -> 14928.766
A29: Rollo C14 1,8mt x 15mts x 2 1/2" | B29: u | C29: 1.8 | E29: 8814.7161 | F29: =(E29*140%)*121% -> 14932.129 | G29: =F29*92% -> 13737.559 | H29: =F29*105% -> 15678.736 | I29: =F29 -> 14932.129 | J29: =F29*105% -> 15678.736 | K29: =F29*110% -> 16425.342
A30: Rollo C14 1,8mt x 10mts x 2 1/2" | B30: u | C30: 1.8 | E30: 5876.4774 | F30: =(E30*140%)*121% -> 9954.7527 | G30: =F30*92% -> 9158.3725 | H30: =F30*105% -> 10452.49 | I30: =F30 -> 9954.7527 | J30: =F30*105% -> 10452.49 | K30: =F30*110% -> 10950.228
A31: Rollo C14 1,8mt x 15mts x 2" | B31: u | C31: 1.8 | E31: 10121.754 | F31: =(E31*140%)*121% -> 17146.252 | G31: =F31*92% -> 15774.552 | H31: =F31*105% -> 18003.564 | I31: =F31 -> 17146.252 | J31: =F31*105% -> 18003.564 | K31: =F31*110% -> 18860.877
A32: Rollo C14 1,8mt x 10mts x 2" | B32: u | C32: 1.8 | E32: 6747.8362 | F32: =(E32*140%)*121% -> 11430.834 | G32: =F32*92% -> 10516.368 | H32: =F32*105% -> 12002.376 | I32: =F32 -> 11430.834 | J32: =F32*105% -> 12002.376 | K32: =F32*110% -> 12573.918
A33: Rollo C14 1,5mt x 15mts x 2 1/2" | B33: u | C33: 1.5 | E33: 7066.205 | F33: =(E33*140%)*121% -> 11970.151 | G33: =F33*92% -> 11012.539 | H33: =F33*105% -> 12568.659 | I33: =F33 -> 11970.151 | J33: =F33*105% -> 12568.659 | K33: =F33*110% -> 13167.166
A34: Rollo C14 1,5mt x 10mts x 2 1/2" | B34: u | C34: 1.5 | E34: 4710.8033 | F34: =(E34*140%)*121% -> 7980.1008 | G34: =F34*92% -> 7341.6927 | H34: =F34*105% -> 8379.1058 | I34: =F34 -> 7980.1008 | J34: =F34*105% -> 8379.1058 | K34: =F34*110% -> 8778.1109
A35: Rollo C14 1,5mt x 15mts x 3" | B35: u | C35: 1.5 | E35: 6421.5304 | F35: =(E35*140%)*121% -> 10878.073 | G35: =F35*92% -> 10007.827 | H35: =F35*105% -> 11421.976 | I35: =F35 -> 10878.073 | J35: =F35*105% -> 11421.976 | K35: =F35*110% -> 11965.88
A36: Rollo C14 1,5mt x 10mts x 3" | B36: u | C36: 1.5 | E36: 4281.0203 | F36: =(E36*140%)*121% -> 7252.0483 | G36: =F36*92% -> 6671.8845 | H36: =F36*105% -> 7614.6508 | I36: =F36 -> 7252.0483 | J36: =F36*105% -> 7614.6508 | K36: =F36*110% -> 7977.2532
... A40: Rollo C12 2mt x 10mts x 2" | B40: u | C40: 2 | E40: 10939.544 | F40: =(E40*140%)*121% -> 18531.587 | G40: =F40*92% -> 17049.06 | H40: =F40*105% -> 19458.166 | I40: =F40 -> 18531.587 | J40: =F40*105% -> 19458.166 | K40: =F40*110% -> 20384.745
A41: Clavos punta paris 2 1/2" | B41: kg | C41: kg | E41: 2829.3058 | F41: =(E41*140%)*121% -> 4792.844 | G41: =F41*92% -> 4409.4165 | H41: =F41*105% -> 5032.4862 | I41: =F41 -> 4792.844 | J41: =F41*105% -> 5032.4862 | K41: =F41*110% -> 5272.1284
A42: Arena | B42: m3 | C42: m3 | E42: 17851.24 | F42: =(E42*140%)*121% -> 30240 | G42: =F42*92% -> 27820.8 | H42: =F42*105% -> 31752 | I42: =F42 -> 30240 | J42: =F42*105% -> 31752 | K42: =F42*110% -> 33264
A43: Ripio | B43: m3 | C43: m3 | E43: 17851.24 | F43: =(E43*140%)*121% -> 30240 | G43: =F43*92% -> 27820.8 | H43: =F43*105% -> 31752 | I43: =F43 -> 30240 | J43: =F43*105% -> 31752 | K43: =F43*110% -> 33264
...
